<sdf version='1.7'>
  <model name='differential_wheeled_robot'>
    <link name='base_footprint'>
      <inertial>
        <pose>0 0 0.079995 0 -0 0</pose>
        <mass>1.5001</mass>
        <inertia>
          <ixx>0.00905897</ixx>
          <ixy>0</ixy>
          <ixz>0</ixz>
          <iyy>0.015109</iyy>
          <iyz>0</iyz>
          <izz>0.0194</izz>
        </inertia>
      </inertial>
      <collision name='base_footprint_fixed_joint_lump__yyf_collision'>
        <pose>0 0 0.1 0 -0 0</pose>
        <geometry>
          <cylinder>
            <length>0.04</length>
            <radius>0.15</radius>
          </cylinder>
        </geometry>
      </collision>
      <collision name='base_footprint_fixed_joint_lump__caster_back_link_collision_1'>
        <pose>-0.11 0 0.04 0 -0 0</pose>
        <geometry>
          <sphere>
            <radius>0.04</radius>
          </sphere>
        </geometry>
        <surface>
          <contact>
            <ode/>
          </contact>
          <friction>
            <ode>
              <mu>0</mu>
              <mu2>0</mu2>
            </ode>
          </friction>
        </surface>
      </collision>
      <collision name='base_footprint_fixed_joint_lump__caster_front_link_collision_2'>
        <pose>0.11 0 0.04 0 -0 0</pose>
        <geometry>
          <sphere>
            <radius>0.04</radius>
          </sphere>
        </geometry>
        <surface>
          <contact>
            <ode/>
          </contact>
          <friction>
            <ode>
              <mu>0</mu>
              <mu2>0</mu2>
            </ode>
          </friction>
        </surface>
      </collision>
      <visual name='base_footprint_visual'>
        <pose>0 0 0 0 -0 0</pose>
        <geometry>
          <box>
            <size>0.001 0.001 0.001</size>
          </box>
        </geometry>
      </visual>
      <visual name='base_footprint_fixed_joint_lump__base_link_visual_1'>
        <pose>0 0 0.1 0 -0 0</pose>
        <geometry>
          <cylinder>
            <length>0.04</length>
            <radius>0.15</radius>
          </cylinder>
        </geometry>
        <material>
          <script>
            <name>Gazebo/Darkgray</name>
            <uri>file://media/materials/scripts/gazebo.material</uri>
          </script>
        </material>
      </visual>
      <visual name='base_footprint_fixed_joint_lump__caster_back_link_visual_2'>
        <pose>-0.11 0 0.04 0 -0 0</pose>
        <geometry>
          <sphere>
            <radius>0.04</radius>
          </sphere>
        </geometry>
      </visual>
      <visual name='base_footprint_fixed_joint_lump__caster_front_link_visual_3'>
        <pose>0.11 0 0.04 0 -0 0</pose>
        <geometry>
          <sphere>
            <radius>0.04</radius>
          </sphere>
        </geometry>
      </visual>
      <visual name='base_footprint_fixed_joint_lump__hokuyo_link_visual_4'>
        <pose>0.125 0 0.15 0 -0 0</pose>
        <geometry>
          <box>
            <size>0.05 0.05 0.05</size>
          </box>
        </geometry>
        <material>
          <script>
            <name>Gazebo/Blue</name>
            <uri>file://media/materials/scripts/gazebo.material</uri>
          </script>
        </material>
      </visual>
      <sensor name='contacts' type='contact'>
        <contact>
          <collision>yyf</collision>
          <topic>__default_topic__</topic>
        </contact>
        <plugin name='gazebo_ros_bumper_controller' filename='libgazebo_ros_bumper.so'>
          <alwaysOn>1</alwaysOn>
          <updateRate>10</updateRate>
          <frameName>base_link</frameName>
          <topicName>/robot_bumper</topicName>
          <visualize>1</visualize>
        </plugin>
        <pose>0 0 0.1 0 -0 0</pose>
      </sensor>
      <gravity>1</gravity>
      <sensor name='head_hokuyo_sensor' type='ray'>
        <visualize>1</visualize>
        <update_rate>100</update_rate>
        <ray>
          <scan>
            <horizontal>
              <samples>37</samples>
              <resolution>1</resolution>
              <min_angle>-1.5708</min_angle>
              <max_angle>1.5708</max_angle>
            </horizontal>
          </scan>
          <range>
            <min>0</min>
            <max>2</max>
            <resolution>0.001</resolution>
          </range>
        </ray>
        <plugin name='gazebo_ros_head_hokuyo_controller' filename='libgazebo_ros_laser.so'>
          <topicName>/scan</topicName>
          <frameName>hokuyo_link</frameName>
        </plugin>
        <pose>0.125 0 0.15 0 -0 0</pose>
      </sensor>
    </link>
    <joint name='front_left_wheel_joint' type='revolute'>
      <pose relative_to='base_footprint'>0 0.14 0.1 0 -0 0</pose>
      <parent>base_footprint</parent>
      <child>front_left_wheel</child>
      <axis>
        <xyz>0 1 0</xyz>
        <limit>
          <effort>100</effort>
          <velocity>100</velocity>
          <lower>-1e+16</lower>
          <upper>1e+16</upper>
        </limit>
        <dynamics>
          <spring_reference>0</spring_reference>
          <spring_stiffness>0</spring_stiffness>
        </dynamics>
      </axis>
    </joint>
    <link name='front_left_wheel'>
      <pose relative_to='front_left_wheel_joint'>0 0 0 0 -0 0</pose>
      <inertial>
        <pose>0 0 0 0 -0 0</pose>
        <mass>0.5</mass>
        <inertia>
          <ixx>0.00126667</ixx>
          <ixy>0</ixy>
          <ixz>0</ixz>
          <iyy>0.00126667</iyy>
          <iyz>0</iyz>
          <izz>0.0025</izz>
        </inertia>
      </inertial>
      <collision name='front_left_wheel_collision'>
        <pose>0 0 0 -1.5708 0 0</pose>
        <geometry>
          <cylinder>
            <length>0.02</length>
            <radius>0.1</radius>
          </cylinder>
        </geometry>
        <surface>
          <contact>
            <ode>
              <kp>1e+07</kp>
              <kd>1</kd>
            </ode>
          </contact>
          <friction>
            <ode>
              <mu>1</mu>
              <mu2>1</mu2>
              <fdir1>1 0 0</fdir1>
            </ode>
          </friction>
        </surface>
      </collision>
      <visual name='front_left_wheel_visual'>
        <pose>0 0 0 -1.5708 0 0</pose>
        <geometry>
          <cylinder>
            <length>0.02</length>
            <radius>0.1</radius>
          </cylinder>
        </geometry>
        <material>
          <script>
            <name>Gazebo/Grey</name>
            <uri>file://media/materials/scripts/gazebo.material</uri>
          </script>
        </material>
      </visual>
      <gravity>1</gravity>
    </link>
    <joint name='front_right_wheel_joint' type='revolute'>
      <pose relative_to='base_footprint'>0 -0.14 0.1 0 -0 0</pose>
      <parent>base_footprint</parent>
      <child>front_right_wheel</child>
      <axis>
        <xyz>0 1 0</xyz>
        <limit>
          <effort>100</effort>
          <velocity>100</velocity>
          <lower>-1e+16</lower>
          <upper>1e+16</upper>
        </limit>
        <dynamics>
          <spring_reference>0</spring_reference>
          <spring_stiffness>0</spring_stiffness>
        </dynamics>
      </axis>
    </joint>
    <link name='front_right_wheel'>
      <pose relative_to='front_right_wheel_joint'>0 0 0 0 -0 0</pose>
      <inertial>
        <pose>0 0 0 0 -0 0</pose>
        <mass>0.5</mass>
        <inertia>
          <ixx>0.00126667</ixx>
          <ixy>0</ixy>
          <ixz>0</ixz>
          <iyy>0.00126667</iyy>
          <iyz>0</iyz>
          <izz>0.0025</izz>
        </inertia>
      </inertial>
      <collision name='front_right_wheel_collision'>
        <pose>0 0 0 -1.5708 0 0</pose>
        <geometry>
          <cylinder>
            <length>0.02</length>
            <radius>0.1</radius>
          </cylinder>
        </geometry>
        <surface>
          <contact>
            <ode>
              <kp>1e+07</kp>
              <kd>1</kd>
            </ode>
          </contact>
          <friction>
            <ode>
              <mu>1</mu>
              <mu2>1</mu2>
              <fdir1>1 0 0</fdir1>
            </ode>
          </friction>
        </surface>
      </collision>
      <visual name='front_right_wheel_visual'>
        <pose>0 0 0 -1.5708 0 0</pose>
        <geometry>
          <cylinder>
            <length>0.02</length>
            <radius>0.1</radius>
          </cylinder>
        </geometry>
        <material>
          <script>
            <name>Gazebo/Grey</name>
            <uri>file://media/materials/scripts/gazebo.material</uri>
          </script>
        </material>
      </visual>
      <gravity>1</gravity>
    </link>
    <static>0</static>
    <plugin name='differential_drive_controller' filename='libgazebo_ros_diff_drive.so'>
      <rosDebugLevel>Debug</rosDebugLevel>
      <publishWheelTF>0</publishWheelTF>
      <robotNamespace>/</robotNamespace>
      <publishTf>1</publishTf>
      <publishWheelJointState>0</publishWheelJointState>
      <alwaysOn>1</alwaysOn>
      <updateRate>100.0</updateRate>
      <leftJoint>front_left_wheel_joint</leftJoint>
      <rightJoint>front_right_wheel_joint</rightJoint>
      <wheelSeparation>0.3</wheelSeparation>
      <wheelDiameter>0.2</wheelDiameter>
      <broadcastTF>1</broadcastTF>
      <wheelTorque>30</wheelTorque>
      <wheelAcceleration>30</wheelAcceleration>
      <commandTopic>cmd_vel</commandTopic>
      <odometryFrame>odom</odometryFrame>
      <odometryTopic>odom</odometryTopic>
      <robotBaseFrame>base_footprint</robotBaseFrame>
    </plugin>
  </model>
</sdf>
